<!-- SELQIE MuJoCo Model -->
<!-- Made by Jonathan Boylan -->
<!-- XML Docs: https://mujoco.readthedocs.io/en/stable/XMLreference.html -->
<mujoco model="selqie">
    <compiler angle="radian" autolimits="true"/>

    <!-- Parameters (in SI Units) -->
    <option timestep="0.002"/>
    <option gravity="0 0 -9.81"/>
    <option density="0" viscosity="0"/> <!-- Fluid dynamics -->
    <option integrator="Euler"/> <!-- Euler, RK4, implicit, implicitfast -->
    <option solver="Newton"/> <!-- PGS, CG, Newton -->

    <!-- Assets -->
    <asset>
        <material name="aluminum" shininess="0.25" rgba="0.5 0.5 0.5 1.0"/>
        <material name="pla" shininess="0" rgba="0.1 0.1 0.1 1.0"/>
    </asset>

    <!-- Model -->
    <worldbody>
        <light name="spotlight" mode="targetbodycom" target="base_link" pos="0 -1 2"/>

        <!-- Base Link Frame -->
        <body name="base_link" pos="0 0 0.5" euler="0 0 0">
            <freejoint/>

            <!-- Body -->
            <inertial pos="0 0 0" mass="1" diaginertia="0.1 0.1 0.1"/>
            <geom type="box" size="0.165 0.075 0.05" material="aluminum"/>
            <geom type="cylinder" size="0.05 0.165" pos="0 0.075 0" euler="0 1.5708 0" material="aluminum"/>
            <geom type="cylinder" size="0.05 0.165" pos="0 -0.075 0" euler="0 1.5708 0" material="aluminum"/>
            
            <!-- Motor Boxes -->
            <geom type="box" size="0.075 0.05 0.05" pos="0.27 0.075 0" material="aluminum"/> <!-- FL -->
            <geom type="box" size="0.075 0.05 0.05" pos="-0.27 0.075 0" material="aluminum"/> <!-- RL -->
            <geom type="box" size="0.075 0.05 0.05" pos="-0.27 -0.075 0" material="aluminum"/> <!-- RR -->
            <geom type="box" size="0.075 0.05 0.05" pos="0.27 -0.075 0" material="aluminum"/> <!-- FR -->

            <!-- Front Left Thigh A Frame -->
            <body pos="0.3 0.1255 0" euler="0 0 0">
                <joint name="motor0" axis="0 1 0"/>
                <inertial pos="0.033 0.005 0" mass="0.05" diaginertia="0.005 0.005 0.005"/>
                <geom type="cylinder" size="0.0075 0.005" pos="0 0.005 0" euler="1.5708 0 0" material="pla"/>
                <geom type="box" size="0.033 0.005 0.0075" pos="0.033 0.005 0" material="pla"/>
                <geom type="cylinder" size="0.0075 0.005" pos="0.066 0.005 0" euler="1.5708 0 0" material="pla"/>

                <!-- Front Left Leg A Frame-->
                <body pos="0.066 0.0105 0" euler="0 0 0">
                    <joint axis="0 1 0"/>
                    <inertial pos="0.075 0.0025 0" mass="0.05" diaginertia="0.005 0.005 0.005"/>
                    <geom type="cylinder" size="0.0075 0.0025" pos="0 0.0025 0" euler="1.5708 0 0" material="pla"/>
                    <geom type="box" size="0.075 0.0025 0.0075" pos="0.075 0.0025 0" material="pla"/>

                    <!-- Front Left Toe A Frame -->
                    <body name="toeFLA" pos="0.15 -0.0005 0" euler="0 0 0">
                        <inertial pos="0 0.003 0" mass="0.05" diaginertia="0.005 0.005 0.005"/>
                        <geom type="cylinder" size="0.015 0.0025" pos="0 0.003 0" euler="1.5708 0 0" material="pla"/>
                    </body>
                </body>
            </body>

            <!-- Front Left Thigh B Frame -->
            <body pos="0.3 0.136 0" euler="0 0 0">
                <joint name="motor1" axis="0 1 0"/>
                <inertial pos="0.033 0.005 0" mass="0.05" diaginertia="0.005 0.005 0.005"/>
                <geom type="cylinder" size="0.0075 0.005" pos="0 0.005 0" euler="1.5708 0 0" material="pla"/>
                <geom type="box" size="0.033 0.005 0.0075" pos="0.033 0.005 0" material="pla"/>
                <geom type="cylinder" size="0.0075 0.005" pos="0.066 0.005 0" euler="1.5708 0 0" material="pla"/>

                <!-- Front Left Leg B Frame-->
                <body pos="0.066 -0.0005 0" euler="0 0 0">
                    <joint axis="0 1 0"/>
                    <inertial pos="0.075 -0.0025 0" mass="0.05" diaginertia="0.005 0.005 0.005"/>
                    <geom type="cylinder" size="0.0075 0.0025" pos="0 -0.0025 0" euler="1.5708 0 0" material="pla"/>
                    <geom type="box" size="0.075 0.0025 0.0075" pos="0.075 -0.0025 0" material="pla"/>

                    <!-- Front Left Toe B Frame -->
                    <body name="toeFLB" pos="0.15 0.0005 0" euler="0 0 0">
                        <inertial pos="0 -0.003 0" mass="0.05" diaginertia="0.005 0.005 0.005"/>
                        <geom type="cylinder" size="0.015 0.0025" pos="0 -0.003 0" euler="1.5708 0 0" material="pla"/>
                    </body>
                </body>
            </body>
        </body>
    </worldbody>

    <equality>
        <connect body1="toeFLA" body2="toeFLB" anchor="0 0 0"/>
    </equality>

    <!-- Actuators -->
    <actuator>
        <motor joint="motor0" ctrlrange="-10 10"/>
        <motor joint="motor1" ctrlrange="-10 10"/>
    </actuator>

</mujoco>